output/results/lobster_5stocks_training.json
{
  "experiment": "DeepLOB trained on public LOBSTER NASDAQ samples",
  "status": "completed",
  "dataset_scope": {
    "symbols": [
      "AAPL",
      "AMZN",
      "GOOG",
      "INTC",
      "MSFT"
    ],
    "date": "2012-06-21",
    "levels": 10,
    "official_sample_page": "https://data.lobsterdata.com/info/DataSamples.php",
    "mirror_repository": "https://huggingface.co/datasets/totalorganfailure/lobster-data",
    "not_equivalent_to_paper_lse_data": true
  },
  "sources": [
    {
      "symbol": "AAPL",
      "date": "2012-06-21",
      "levels": 10,
      "raw_path": "/Users/jiaqianxing/Documents/GitHub/DeepLOB-Deep-Convolutional-Neural-Networks-for-Limit-Order-Books/data/raw/lobster_samples/AAPL_2012-06-21_34200000_57600000_orderbook_10.csv",
      "download_url": "https://huggingface.co/datasets/totalorganfailure/lobster-data/resolve/main/LOBSTER_SampleFile_AAPL_2012-06-21_10/AAPL_2012-06-21_34200000_57600000_orderbook_10.csv",
      "bytes": 93481244,
      "sha256": "ed75450031996e81bdc5fc985f6afe6851c81d7b2b39bccf13c56d845fe6ff5d"
    },
    {
      "symbol": "AMZN",
      "date": "2012-06-21",
      "levels": 10,
      "raw_path": "/Users/jiaqianxing/Documents/GitHub/DeepLOB-Deep-Convolutional-Neural-Networks-for-Limit-Order-Books/data/raw/lobster_samples/AMZN_2012-06-21_34200000_57600000_orderbook_10.csv",
      "download_url": "https://huggingface.co/datasets/totalorganfailure/lobster-data/resolve/main/LOBSTER_SampleFile_AMZN_2012-06-21_10/AMZN_2012-06-21_34200000_57600000_orderbook_10.csv",
      "bytes": 63216242,
      "sha256": "decfe952b3fa06c9922dc8fba763a37a0fb032d4231767997e4abf2aa0d29b50"
    },
    {
      "symbol": "GOOG",
      "date": "2012-06-21",
      "levels": 10,
      "raw_path": "/Users/jiaqianxing/Documents/GitHub/DeepLOB-Deep-Convolutional-Neural-Networks-for-Limit-Order-Books/data/raw/lobster_samples/GOOG_2012-06-21_34200000_57600000_orderbook_10.csv",
      "download_url": "https://huggingface.co/datasets/totalorganfailure/lobster-data/resolve/main/LOBSTER_SampleFile_GOOG_2012-06-21_10/GOOG_2012-06-21_34200000_57600000_orderbook_10.csv",
      "bytes": 34073243,
      "sha256": "9ebe00b4f1aee57aa73dcb979e1074d16554296ca32b87440ce756c60974bb53"
    },
    {
      "symbol": "INTC",
      "date": "2012-06-21",
      "levels": 10,
      "raw_path": "/Users/jiaqianxing/Documents/GitHub/DeepLOB-Deep-Convolutional-Neural-Networks-for-Limit-Order-Books/data/raw/lobster_samples/INTC_2012-06-21_34200000_57600000_orderbook_10.csv",
      "download_url": "https://huggingface.co/datasets/totalorganfailure/lobster-data/resolve/main/LOBSTER_SampleFile_INTC_2012-06-21_10/INTC_2012-06-21_34200000_57600000_orderbook_10.csv",
      "bytes": 158466105,
      "sha256": "6bc4c4dc1e92d78e46d04f9e7914df2d8c2a9231928493e7395a9085e1fc91ab"
    },
    {
      "symbol": "MSFT",
      "date": "2012-06-21",
      "levels": 10,
      "raw_path": "/Users/jiaqianxing/Documents/GitHub/DeepLOB-Deep-Convolutional-Neural-Networks-for-Limit-Order-Books/data/raw/lobster_samples/MSFT_2012-06-21_34200000_57600000_orderbook_10.csv",
      "download_url": "https://huggingface.co/datasets/totalorganfailure/lobster-data/resolve/main/LOBSTER_SampleFile_MSFT_2012-06-21_10/MSFT_2012-06-21_34200000_57600000_orderbook_10.csv",
      "bytes": 170192771,
      "sha256": "ec2f53467cf7bfb00b5702381bea7b4a061bb4c1730454df3679b272b3561c0e"
    }
  ],
  "data_quality": [
    {
      "symbol": "AAPL",
      "rows": 400391,
      "columns": 40,
      "invalid_rows_removed": 0,
      "finite": true,
      "best_ask_strictly_above_best_bid": true,
      "ask_levels_monotone": true,
      "bid_levels_monotone": true,
      "mid_price_min_fixed_point": 5774800.0,
      "mid_price_max_fixed_point": 5881850.0,
      "processed_feature_path": "/Users/jiaqianxing/Documents/GitHub/DeepLOB-Deep-Convolutional-Neural-Networks-for-Limit-Order-Books/data/processed/lobster_samples/AAPL_2012-06-21_features.npy",
      "processed_mid_price_path": "/Users/jiaqianxing/Documents/GitHub/DeepLOB-Deep-Convolutional-Neural-Networks-for-Limit-Order-Books/data/processed/lobster_samples/AAPL_2012-06-21_mid_prices.npy",
      "duration_seconds": 0.6971484169989708
    },
    {
      "symbol": "AMZN",
      "rows": 269748,
      "columns": 40,
      "invalid_rows_removed": 0,
      "finite": true,
      "best_ask_strictly_above_best_bid": true,
      "ask_levels_monotone": true,
      "bid_levels_monotone": true,
      "mid_price_min_fixed_point": 2205200.0,
      "mid_price_max_fixed_point": 2260250.0,
      "processed_feature_path": "/Users/jiaqianxing/Documents/GitHub/DeepLOB-Deep-Convolutional-Neural-Networks-for-Limit-Order-Books/data/processed/lobster_samples/AMZN_2012-06-21_features.npy",
      "processed_mid_price_path": "/Users/jiaqianxing/Documents/GitHub/DeepLOB-Deep-Convolutional-Neural-Networks-for-Limit-Order-Books/data/processed/lobster_samples/AMZN_2012-06-21_mid_prices.npy",
      "duration_seconds": 0.45761491599841975
    },
    {
      "symbol": "GOOG",
      "rows": 147916,
      "columns": 40,
      "invalid_rows_removed": 0,
      "finite": true,
      "best_ask_strictly_above_best_bid": true,
      "ask_levels_monotone": true,
      "bid_levels_monotone": true,
      "mid_price_min_fixed_point": 5637300.0,
      "mid_price_max_fixed_point": 5798150.0,
      "processed_feature_path": "/Users/jiaqianxing/Documents/GitHub/DeepLOB-Deep-Convolutional-Neural-Networks-for-Limit-Order-Books/data/processed/lobster_samples/GOOG_2012-06-21_features.npy",
      "processed_mid_price_path": "/Users/jiaqianxing/Documents/GitHub/DeepLOB-Deep-Convolutional-Neural-Networks-for-Limit-Order-Books/data/processed/lobster_samples/GOOG_2012-06-21_mid_prices.npy",
      "duration_seconds": 0.2516648750024615
    },
    {
      "symbol": "INTC",
      "rows": 624040,
      "columns": 40,
      "invalid_rows_removed": 0,
      "finite": true,
      "best_ask_strictly_above_best_bid": true,
      "ask_levels_monotone": true,
      "bid_levels_monotone": true,
      "mid_price_min_fixed_point": 266150.0,
      "mid_price_max_fixed_point": 275950.0,
      "processed_feature_path": "/Users/jiaqianxing/Documents/GitHub/DeepLOB-Deep-Convolutional-Neural-Networks-for-Limit-Order-Books/data/processed/lobster_samples/INTC_2012-06-21_features.npy",
      "processed_mid_price_path": "/Users/jiaqianxing/Documents/GitHub/DeepLOB-Deep-Convolutional-Neural-Networks-for-Limit-Order-Books/data/processed/lobster_samples/INTC_2012-06-21_mid_prices.npy",
      "duration_seconds": 1.081581875001575
    },
    {
      "symbol": "MSFT",
      "rows": 668765,
      "columns": 40,
      "invalid_rows_removed": 0,
      "finite": true,
      "best_ask_strictly_above_best_bid": true,
      "ask_levels_monotone": true,
      "bid_levels_monotone": true,
      "mid_price_min_fixed_point": 300650.0,
      "mid_price_max_fixed_point": 311400.0,
      "processed_feature_path": "/Users/jiaqianxing/Documents/GitHub/DeepLOB-Deep-Convolutional-Neural-Networks-for-Limit-Order-Books/data/processed/lobster_samples/MSFT_2012-06-21_features.npy",
      "processed_mid_price_path": "/Users/jiaqianxing/Documents/GitHub/DeepLOB-Deep-Convolutional-Neural-Networks-for-Limit-Order-Books/data/processed/lobster_samples/MSFT_2012-06-21_mid_prices.npy",
      "duration_seconds": 1.1849320419969445
    }
  ],
  "split_method": "per-symbol chronological 70%/15%/15%; windows and targets stay inside each split",
  "split_bounds": {
    "AAPL": {
      "train": [
        0,
        280273
      ],
      "validation": [
        280273,
        340332
      ],
      "test": [
        340332,
        400391
      ]
    },
    "AMZN": {
      "train": [
        0,
        188823
      ],
      "validation": [
        188823,
        229285
      ],
      "test": [
        229285,
        269748
      ]
    },
    "GOOG": {
      "train": [
        0,
        103541
      ],
      "validation": [
        103541,
        125728
      ],
      "test": [
        125728,
